[2023-12-25T12:55:26.435+0000] {taskinstance.py:1159} INFO - Dependencies all met for dep_context=non-requeueable deps ti=<TaskInstance: ETL_toll_data.unzip_data scheduled__2023-12-22T00:00:00+00:00 [queued]>
[2023-12-25T12:55:26.487+0000] {taskinstance.py:1159} INFO - Dependencies all met for dep_context=requeueable deps ti=<TaskInstance: ETL_toll_data.unzip_data scheduled__2023-12-22T00:00:00+00:00 [queued]>
[2023-12-25T12:55:26.488+0000] {taskinstance.py:1361} INFO - Starting attempt 1 of 2
[2023-12-25T12:55:26.538+0000] {taskinstance.py:1382} INFO - Executing <Task(BashOperator): unzip_data> on 2023-12-22 00:00:00+00:00
[2023-12-25T12:55:26.583+0000] {standard_task_runner.py:57} INFO - Started process 51 to run task
[2023-12-25T12:55:26.634+0000] {standard_task_runner.py:84} INFO - Running: ['***', 'tasks', 'run', 'ETL_toll_data', 'unzip_data', 'scheduled__2023-12-22T00:00:00+00:00', '--job-id', '299', '--raw', '--subdir', 'DAGS_FOLDER/ETL_toll_data.py', '--cfg-path', '/tmp/tmpcjhb6kh2']
[2023-12-25T12:55:26.641+0000] {standard_task_runner.py:85} INFO - Job 299: Subtask unzip_data
[2023-12-25T12:55:26.921+0000] {task_command.py:416} INFO - Running <TaskInstance: ETL_toll_data.unzip_data scheduled__2023-12-22T00:00:00+00:00 [running]> on host 227737b5950b
[2023-12-25T12:55:27.183+0000] {taskinstance.py:1662} INFO - Exporting env vars: AIRFLOW_CTX_DAG_EMAIL='chibuikeokenu@gmail.com' AIRFLOW_CTX_DAG_OWNER='Golstine' AIRFLOW_CTX_DAG_ID='ETL_toll_data' AIRFLOW_CTX_TASK_ID='unzip_data' AIRFLOW_CTX_EXECUTION_DATE='2023-12-22T00:00:00+00:00' AIRFLOW_CTX_TRY_NUMBER='1' AIRFLOW_CTX_DAG_RUN_ID='scheduled__2023-12-22T00:00:00+00:00'
[2023-12-25T12:55:27.185+0000] {subprocess.py:63} INFO - Tmp dir root location: /tmp
[2023-12-25T12:55:27.186+0000] {subprocess.py:75} INFO - Running command: ['/bin/bash', '-c', 'tar -zxvf /opt/***/logs/tolldata.tgz -C /opt/***/logs/']
[2023-12-25T12:55:27.219+0000] {subprocess.py:86} INFO - Output:
[2023-12-25T12:55:27.258+0000] {subprocess.py:93} INFO - fileformats.txt
[2023-12-25T12:55:27.259+0000] {subprocess.py:93} INFO - tar: fileformats.txt: Cannot open: File exists
[2023-12-25T12:55:27.259+0000] {subprocess.py:93} INFO - payment-data.txt
[2023-12-25T12:55:27.271+0000] {subprocess.py:93} INFO - ._tollplaza-data.tsv
[2023-12-25T12:55:27.274+0000] {subprocess.py:93} INFO - tollplaza-data.tsv
[2023-12-25T12:55:27.290+0000] {subprocess.py:93} INFO - ._vehicle-data.csv
[2023-12-25T12:55:27.295+0000] {subprocess.py:93} INFO - vehicle-data.csv
[2023-12-25T12:55:27.305+0000] {subprocess.py:93} INFO - tar: Exiting with failure status due to previous errors
[2023-12-25T12:55:27.310+0000] {subprocess.py:97} INFO - Command exited with return code 2
[2023-12-25T12:55:27.343+0000] {taskinstance.py:1937} ERROR - Task failed with exception
Traceback (most recent call last):
  File "/home/airflow/.local/lib/python3.8/site-packages/airflow/operators/bash.py", line 210, in execute
    raise AirflowException(
airflow.exceptions.AirflowException: Bash command failed. The command returned a non-zero exit code 2.
[2023-12-25T12:55:27.353+0000] {taskinstance.py:1400} INFO - Marking task as UP_FOR_RETRY. dag_id=ETL_toll_data, task_id=unzip_data, execution_date=20231222T000000, start_date=20231225T125526, end_date=20231225T125527
[2023-12-25T12:55:27.407+0000] {warnings.py:109} WARNING - /home/***/.local/lib/python3.8/site-packages/***/utils/email.py:154: RemovedInAirflow3Warning: Fetching SMTP credentials from configuration variables will be deprecated in a future release. Please set credentials using a connection instead.
  send_mime_email(e_from=mail_from, e_to=recipients, mime_msg=msg, conn_id=conn_id, dryrun=dryrun)

[2023-12-25T12:55:27.407+0000] {configuration.py:1050} WARNING - section/key [smtp/smtp_user] not found in config
[2023-12-25T12:55:27.408+0000] {email.py:270} INFO - Email alerting: attempt 1
[2023-12-25T12:55:27.426+0000] {configuration.py:1050} WARNING - section/key [smtp/smtp_user] not found in config
[2023-12-25T12:55:27.426+0000] {email.py:270} INFO - Email alerting: attempt 1
[2023-12-25T12:55:27.427+0000] {taskinstance.py:2007} ERROR - Failed to send email to: ['chibuikeokenu@gmail.com']
Traceback (most recent call last):
  File "/home/airflow/.local/lib/python3.8/site-packages/airflow/models/taskinstance.py", line 1518, in _run_raw_task
    self._execute_task_with_callbacks(context, test_mode, session=session)
  File "/home/airflow/.local/lib/python3.8/site-packages/airflow/models/taskinstance.py", line 1681, in _execute_task_with_callbacks
    result = self._execute_task(context, task_orig)
  File "/home/airflow/.local/lib/python3.8/site-packages/airflow/models/taskinstance.py", line 1744, in _execute_task
    result = execute_callable(context=context, **execute_callable_kwargs)
  File "/home/airflow/.local/lib/python3.8/site-packages/airflow/operators/bash.py", line 210, in execute
    raise AirflowException(
airflow.exceptions.AirflowException: Bash command failed. The command returned a non-zero exit code 2.

During handling of the above exception, another exception occurred:

Traceback (most recent call last):
  File "/home/airflow/.local/lib/python3.8/site-packages/airflow/models/taskinstance.py", line 2420, in email_alert
    send_email(task.email, subject, html_content)
  File "/home/airflow/.local/lib/python3.8/site-packages/airflow/utils/email.py", line 80, in send_email
    return backend(
  File "/home/airflow/.local/lib/python3.8/site-packages/airflow/utils/email.py", line 154, in send_email_smtp
    send_mime_email(e_from=mail_from, e_to=recipients, mime_msg=msg, conn_id=conn_id, dryrun=dryrun)
  File "/home/airflow/.local/lib/python3.8/site-packages/airflow/utils/email.py", line 272, in send_mime_email
    smtp_conn = _get_smtp_connection(smtp_host, smtp_port, smtp_timeout, smtp_ssl)
  File "/home/airflow/.local/lib/python3.8/site-packages/airflow/utils/email.py", line 316, in _get_smtp_connection
    return smtplib.SMTP(host=host, port=port, timeout=timeout)
  File "/usr/local/lib/python3.8/smtplib.py", line 255, in __init__
    (code, msg) = self.connect(host, port)
  File "/usr/local/lib/python3.8/smtplib.py", line 339, in connect
    self.sock = self._get_socket(host, port, self.timeout)
  File "/usr/local/lib/python3.8/smtplib.py", line 310, in _get_socket
    return socket.create_connection((host, port), timeout,
  File "/usr/local/lib/python3.8/socket.py", line 808, in create_connection
    raise err
  File "/usr/local/lib/python3.8/socket.py", line 796, in create_connection
    sock.connect(sa)
OSError: [Errno 99] Cannot assign requested address

During handling of the above exception, another exception occurred:

Traceback (most recent call last):
  File "/home/airflow/.local/lib/python3.8/site-packages/airflow/models/taskinstance.py", line 2005, in handle_failure
    self.email_alert(error, task)
  File "/home/airflow/.local/lib/python3.8/site-packages/airflow/models/taskinstance.py", line 2422, in email_alert
    send_email(task.email, subject, html_content_err)
  File "/home/airflow/.local/lib/python3.8/site-packages/airflow/utils/email.py", line 80, in send_email
    return backend(
  File "/home/airflow/.local/lib/python3.8/site-packages/airflow/utils/email.py", line 154, in send_email_smtp
    send_mime_email(e_from=mail_from, e_to=recipients, mime_msg=msg, conn_id=conn_id, dryrun=dryrun)
  File "/home/airflow/.local/lib/python3.8/site-packages/airflow/utils/email.py", line 272, in send_mime_email
    smtp_conn = _get_smtp_connection(smtp_host, smtp_port, smtp_timeout, smtp_ssl)
  File "/home/airflow/.local/lib/python3.8/site-packages/airflow/utils/email.py", line 316, in _get_smtp_connection
    return smtplib.SMTP(host=host, port=port, timeout=timeout)
  File "/usr/local/lib/python3.8/smtplib.py", line 255, in __init__
    (code, msg) = self.connect(host, port)
  File "/usr/local/lib/python3.8/smtplib.py", line 339, in connect
    self.sock = self._get_socket(host, port, self.timeout)
  File "/usr/local/lib/python3.8/smtplib.py", line 310, in _get_socket
    return socket.create_connection((host, port), timeout,
  File "/usr/local/lib/python3.8/socket.py", line 808, in create_connection
    raise err
  File "/usr/local/lib/python3.8/socket.py", line 796, in create_connection
    sock.connect(sa)
OSError: [Errno 99] Cannot assign requested address
[2023-12-25T12:55:27.458+0000] {standard_task_runner.py:104} ERROR - Failed to execute job 299 for task unzip_data (Bash command failed. The command returned a non-zero exit code 2.; 51)
[2023-12-25T12:55:27.481+0000] {local_task_job_runner.py:228} INFO - Task exited with return code 1
[2023-12-25T12:55:27.528+0000] {taskinstance.py:2778} INFO - 0 downstream tasks scheduled from follow-on schedule check
